Workbook

Sheet README
A1: ACEG Coding Workbook — QM640 Capstone, Group 3
A2: Purpose: double coding of the 223 frozen cases against the ACEG Framework v1 (docs/codebook.md).
A4: Which cells to edit
A5: Coder1 / Coder2 sheets: only the YELLOW cells (d1–d8, primary_domain, c01–c20, covered, notes). Use the dropdowns.
A6: Gold sheet: only blank YELLOW cells where the coders disagreed; type the agreed value after discussion.
A7: Tracker sheet: coder names in the YELLOW cells. All other cells are formulas or source data — do not edit.
A9: Coding rules (summary — full rules in docs/codebook.md)
A10: 1. Read the case on the Cases sheet (title, description, link). Use only what the advisory says.
A11: 2. d1–d8: 1 if the advisory shows that domain's requirement was breached or could be breached; otherwise 0.
A12: 3. primary_domain: the single domain (1–8) that most directly enabled the weakness; it must be one coded 1.
A13: 4. c01–c20: for controls linked to a domain coded 1, enter 1 = breached (absent, failed or bypassed) or 0 = not breached. Enter NA for controls whose domain is 0 (those cells turn grey).
A14: 5. covered: 1 if at least one breached control would plausibly have prevented the weakness; 0 if the framework has no control for it.
... A24: Example (case CA-018, CVE-2025-54795 — approval-prompt bypass in Claude Code)
A25: d1 | B25: d2 | C25: d3 | D25: d4 | E25: d5 | F25: d6 | G25: d7 | H25: d8 | I25: primary_domain | J25: c01 | K25: c02 | L25: c03 | M25: c08 | N25: c09 | O25: other controls | P25: covered | Q25: n_applicable | R25: n_breached | S25: gcs
A26: 1 | B26: 0 | C26: 0 | D26: 1 | E26: 0 | F26: 0 | G26: 0 | H26: 0 | I26: 1 | J26: 0 | K26: 1 | L26: 0 | M26: 1 | N26: 0 | O26: NA | P26: 1 | Q26: 5 | R26: 2 | S26: 60
A28: Note: column A on this sheet holds long text; widen it or read in the formula bar.

Sheet Tracker
A1: Role | B1: Name
A2: Coder 1
A3: Coder 2
A4: Adjudicator (if the coders cannot agree)
A6: Batch | B6: Cases | C6: Week due | D6: Coder 1 done | E6: Coder 2 done | F6: Both done, full agreement | G6: Gold complete
A7: W2 pilot | B7: =COUNTIF(Cases!$B$2:$B$224,A7) | C7: Week 2 | D7: =SUMPRODUCT((Coder1!$B$2:$B$224=A7)*(Coder1!$AN$2:$AN$224=1)) | E7: =SUMPRODUCT((Coder2!$B$2:$B$224=A7)*(Coder2!$AN$2:$AN$224=1)) | F7: =SUMPRODUCT((Gold!$B$2:$B$224=A7)*(Gold!$AN$2:$AN$224=1)) | G7: =SUMPRODUCT((Gold!$B$2:$B$224=A7)*(Gold!$AM$2:$AM$224=""))
A8: W3 | B8: =COUNTIF(Cases!$B$2:$B$224,A8) | C8: Week 3 | D8: =SUMPRODUCT((Coder1!$B$2:$B$224=A8)*(Coder1!$AN$2:$AN$224=1)) | E8: =SUMPRODUCT((Coder2!$B$2:$B$224=A8)*(Coder2!$AN$2:$AN$224=1)) | F8: =SUMPRODUCT((Gold!$B$2:$B$224=A8)*(Gold!$AN$2:$AN$224=1)) | G8: =SUMPRODUCT((Gold!$B$2:$B$224=A8)*(Gold!$AM$2:$AM$224=""))
A9: W4 | B9: =COUNTIF(Cases!$B$2:$B$224,A9) | C9: Week 4 | D9: =SUMPRODUCT((Coder1!$B$2:$B$224=A9)*(Coder1!$AN$2:$AN$224=1)) | E9: =SUMPRODUCT((Coder2!$B$2:$B$224=A9)*(Coder2!$AN$2:$AN$224=1)) | F9: =SUMPRODUCT((Gold!$B$2:$B$224=A9)*(Gold!$AN$2:$AN$224=1)) | G9: =SUMPRODUCT((Gold!$B$2:$B$224=A9)*(Gold!$AM$2:$AM$224=""))
A10: W5 | B10: =COUNTIF(Cases!$B$2:$B$224,A10) | C10: Week 5 | D10: =SUMPRODUCT((Coder1!$B$2:$B$224=A10)*(Coder1!$AN$2:$AN$224=1)) | E10: =SUMPRODUCT((Coder2!$B$2:$B$224=A10)*(Coder2!$AN$2:$AN$224=1)) | F10: =SUMPRODUCT((Gold!$B$2:$B$224=A10)*(Gold!$AN$2:$AN$224=1)) | G10: =SUMPRODUCT((Gold!$B$2:$B$224=A10)*(Gold!$AM$2:$AM$224=""))
A11: Total | B11: =SUM(B7:B10) | D11: =SUM(D7:D10) | E11: =SUM(E7:E10) | F11: =SUM(F7:F10) | G11: =SUM(G7:G10)

Sheet Codebook
A1: Code | B1: Domain | C1: Family | D1: Linked controls
A2: D1 | B2: Agency and action control | C2: A | D2: C01, C02, C03
A3: D2 | B3: Instruction and boundary adherence | C3: A | D3: C04, C05
A4: D3 | B4: Transparency and honest reporting | C4: D | D4: C06, C07
A5: D4 | B5: Input trust and goal integrity | C5: B | D5: C08, C09
A6: D5 | B6: Secrets and data protection | C6: C | D6: C10, C11
A7: D6 | B7: Code and supply-chain integrity | C7: B | D7: C12, C13, C14
A8: D7 | B8: Accountability and recoverability | C8: D | D8: C15, C16, C17
A9: D8 | B9: Human oversight and appropriate reliance | C9: A | D9: C18, C19, C20
A11: Code | B11: Control | C11: Domain
A12: C01 | B12: Least-privilege credentials and tool permissions | C12: D1
A13: C02 | B13: Human approval gate for sensitive or irreversible actions | C13: D1
A14: C03 | B14: Execution isolation (sandbox; dev/prod separation) | C14: D1
A15: C04 | B15: Machine-enforced policy limits (deny rules, ignore files, allowlists) | C15: D2
A16: C05 | B16: Workspace trust and scope confirmation before execution | C16: D2
A17: C06 | B17: Faithful disclosure of planned actions (full arguments shown) | C17: D3
A18: C07 | B18: Tamper-evident action logs | C18: D3
A19: C08 | B19: Isolation and sanitization of untrusted inputs | C19: D4
A20: C09 | B20: Allow-listed, integrity-checked tools and MCP servers | C20: D4
A21: C10 | B21: Secret scanning, redaction and protected credential storage | C21: D5
A22: C11 | B22: Network egress limits and data-handling policy | C22: D5
... A31: C20 | B31: Capability and limitation disclosure to users | C31: D8
A33: Families | B33: A = Agency and oversight (D1, D2, D8); B = Input and code integrity (D4, D6); C = Data protection (D5); D = Transparency and accountability (D3, D7)

Sheet Cases
A1: case_id | B1: batch | C1: product | D1: component_type | E1: published | F1: title | G1: description | H1: url
A2: CA-013 | B2: W2 pilot | C2: Cursor | D2: agent product | E2: 2025-08-01 | F2: Cursor bypasses its allow list to execute arbitrary commands | G2: Cursor is a code editor built for programming with AI. In versions below 1.3, an attacker can bypass the allow list in auto-run mode with a backtick (`) or $(cmd). If a user has swapped Cursor from its default settings (requiring approval for every terminal call) to an allowlist, an attacker can execute arbitrary command execution outside of the allowlist without user approval. An attacker can trigger this vulnerability if chained with indirect prompt injection. This is fixed in version 1.3. | H2: https://www.cve.org/CVERecord?id=CVE-2025-54131
A3: CA-020 | B3: W2 pilot | C3: Cursor | D3: agent product | E3: 2025-08-05 | F3: Cursor Agent is vulnerable to prompt injection via MCP Special Files | G3: Cursor is a code editor built for programming with AI. Cursor allows writing in-workspace files with no user approval in versions below 1.3.9, If the file is a dotfile, editing it requires approval but creating a new one doesn't. Hence, if sensitive MCP files, such as the .cursor/mcp.json file don't already exist in the workspace, an attacker can chain a indirect prompt injection vulnerability to hijack the context to write to the settings file and trigger RCE on the victim without user approval. This is fixed in version 1.3.9. | H3: https://www.cve.org/CVERecord?id=CVE-2025-54135
A4: CA-026 | B4: W2 pilot | C4: Roo Code | D4: agent product | E4: 2025-08-22 | F4: Roo-Code potential remote code execution via auto-execute command parsing flaw | G4: Roo Code is an AI-powered autonomous coding agent that lives in users' editors. In versions prior to 3.25.5, Roo-Code fails to properly handle process substitution and single ampersand characters in the command parsing logic for auto-execute commands. If a user has enabled auto-approved execution for a command such as ls, an attacker who can submit crafted prompts to the agent may inject arbitrary commands to be executed alongside the intended command. Exploitation requires attacker access to submit prompts and for the user to have enabled auto-approved command execution, which is disabled by default. This vulnerability could allow an attacker to execute arbitrary code. The issue is fixed in version 3.25.5. | H4: https://www.cve.org/CVERecord?id=CVE-2025-57771
A5: CA-035 | B5: W2 pilot | C5: Claude Code | D5: agent product | E5: 2025-09-10 | F5: Claude Code vulnerable to arbitrary code execution caused by maliciously configured git email | G5: At startup, Claude Code constructed a shell command that interpolated the value of `git config user.email` from the current workspace. If an attacker controlled the repository’s Git config (e.g., via a malicious `.git/config`) and set `user.email` to a crafted payload, the unescaped interpolation could trigger arbitrary command execution **before** the user accepted the workspace-trust dialog. The issue affects versions prior to `1.0.105`. The fix in `1.0.105` avoids executing commands built from untrusted configuration and properly validates/escapes inputs. * **Patches:** Update to `@anthropic-ai/claude-code` `1.0.105` or later. * **Workarounds:** Open only trusted workspaces and inspect repository `.git/config` before launch; avoid inheriting untrusted Git configuration values. > Thank you to the NVIDIA AI Red Team for reporting this issue! | H5: https://github.com/advisories/GHSA-j4h9-wv2m-wrf7
A6: CA-085 | B6: W2 pilot | C6: GitHub Copilot | D6: agent product | E6: 2026-02-10 | F6: GitHub Copilot and Visual Studio Code Remote Code Execution Vulnerability | G6: Time-of-check time-of-use (toctou) race condition in GitHub Copilot and Visual Studio allows an authorized attacker to execute code over a network. | H6: https://www.cve.org/CVERecord?id=CVE-2026-21523
A7: CA-088 | B7: W2 pilot | C7: Other coding agent | D7: agent product | E7: 2026-03-05 | F7: Trivy Vulnerability Scanner: Unauthorized AI Agent Execution Code Included in OpenVSX Extension Release | G7: Trivy Vulnerability Scanner is a VS Code extension that helps find vulnerabilities. In Trivy VSCode Extension version 1.8.12, which was distributed via OpenVSX marketplace was compromised and contained malicious code designed to leverage local AI coding agent to collect and exfiltrate sensitive information. Users using the affected artifact are advised to immediately remove it and rotate environment secrets. The malicious artifact has been removed from the marketplace. No other affected artifacts have been identified. | H7: https://www.cve.org/CVERecord?id=CVE-2026-28353
A8: CA-090 | B8: W2 pilot | C8: Claude Code | D8: ecosystem | E8: 2026-03-10 | F8: @siteboon/claude-code-ui is Vulnerable to Shell Command Injection in Git Routes | G8: # Shell Command Injection in User Git Config Endpoint | Field | Value | |-------|-------| | **Severity** | High | | **CVSS 3.1** | 8.8 (High) — when chained with VULN-01 | | **CWE** | CWE-78: Improper Neutralization of Special Elements used in an OS Command ('OS Command Injection') | | **Attack Vector** | Network | | **Authentication** | JWT required (bypassable via VULN-01) | | **Affected Files** | `server/routes/user.js` (lines 58-59) | ## Description The `/api/user/git-config` endpoint constructs shell commands by interpolating user-supplied `gitName` and `gitEmail` values into command strings passed to `child_process.exec()`. The input is placed within double quotes and only `"` is escaped, but backticks (`` ` ``), `$()` command substitution, and `\` sequences are all interpreted within double-quoted strings in bash. This allows authenticated attackers to execute arbitrary OS commands via the git configuration endpoint. ## Root Cause `server/routes/user.js` lines 58-59: ```javascript await execAsync(`git config --global user.name "${gitName.replace(/"/g, '\\"')}"`); await execAsync(`git config --global user.email "${gitEmail.replace(/"/g, '\\"')}"`); ``` Only `"` is escaped. However, within double-quoted bash strings, the following are still interpreted: - `` `malicious_command` `` — backtick execution - `$(malicious_command)` — subshell execution ## Impact - **Remote Code Execution (RCE)** — arbitrary OS commands execute as the Node.js process user - The `git config --global` vector modifies the **server-wide** git configuration, affecting all git operations - When chained with VULN-01 (hardcoded JWT), this is fully **unauthenticated RCE** - Attacker can: read/write any file, install backdoors, pivot to other systems, exfiltrate data ## Proof of Concept ```bash # Step 1: Forge a JWT (see VULN-01) TOKEN=$(python3 -c "import jwt; print(jwt.encode({'userId':1,'username':'admin'}, 'claude-ui-dev-secret-change-in-production', algorithm='HS256'))") # Step 2: Inject via gitName using command substitution curl -X POST "http://REDACTED:5173/api/user/git-config" \ -H "Authorization: Bearer $TOKEN" \ -H "Content-Type: application/json" \ -d '{"gitName":"$(id)","gitEmail":"attacker@example.com"}' ``` The server executes: ``` git config --global user.name "$(id)" ``` Bash evaluates `$(id)` before passing it to git, executing the `id` command and setting the username to the output. ## Remediation Replace `exec()` with `spawn()` (array arguments, no shell): ```javascript // BEFORE (vulnerable): await execAsync(`git config --global user.name "${gitName.replace(/"/g, '\\"')}"`); // AFTER (safe): await spawnAsync('git', ['config', '--global', 'user.name', gitName]); await spawnAsync('git', ['config', '--global', 'user.email', gitEmail]); ``` | H8: https://github.com/advisories/GHSA-7fv4-fmmc-86g2
A9: CA-110 | B9: W2 pilot | C9: Claude Code | D9: agent product | E9: 2026-04-17 | F9: Claude Code: Insecure System-Wide Configuration Loading Enables Local Privilege Escalation on Windows | G9: On Windows, Claude Code loaded system-wide default configuration from `C:\ProgramData\ClaudeCode\managed-settings.json` without validating directory ownership or access permissions. Because the `ProgramData` directory is writable by non-administrative users by default and the `ClaudeCode` subdirectory was not pre-created or access-restricted, a low-privileged local user could create this directory and place a malicious configuration file that would be automatically loaded for any user launching Claude Code on the same machine. Exploiting this would have required a shared multi-user Windows system and a victim user to launch Claude Code after the malicious configuration was placed. Users on standard Claude Code auto-update have received this fix already. Users performing manual updates are advised to update to the latest version. Thank you to hackerone.com/edbr for reporting this issue. | H9: https://github.com/advisories/GHSA-5cwg-9f6j-9jvx
A10: CA-113 | B10: W2 pilot | C10: Gemini CLI | D10: agent product | E10: 2026-04-24 | F10: Gemini CLI: Remote Code Execution via workspace trust and tool allowlisting bypasses | G10: # Summary Gemini CLI (`@google/gemini-cli`) and the `run-gemini-cli` GitHub Action are being updated to harden workspace trust and tool allowlisting, in particular when used in untrusted environments like GitHub Actions. This update introduces a breaking change to how non-interactive (headless) environments handle folder trust, which may impact existing CI/CD workflows under specific conditions. # Details Folder Trust in Headless Mode In previous versions, Gemini CLI running in CI environments (headless mode) automatically trusted workspace folders for the purpose of loading configuration and environment variables. This is potentially risky in situations where Gemini CLI runs on untrusted folders in headless mode (e.g. CI workflows that review user-submitted pull requests). If used with untrusted directory contents, this could lead to remote code execution via malicious environment variables in the local `.gemini/` directory. To ensure consistency and user control, the latest update aligns headless mode behavior with interactive mode, requiring folders to be explicitly trusted before configuration files (such as `.env`) are processed. As a result of this change, GitHub Actions and other automated pipelines that rely on the previous automatic trust behavior will fail to load workspace-specific settings until they are updated to use explicit trust mechanisms. Tool Allowlisting under \--yolo In previous versions, when Gemini CLI was configured to run in `--yolo` mode, it would ignore any fine grained tool allowlist in `~/.gemini/settings.json` (e.g. `run_shell_command(echo)` would allow any command). This is potentially risky in situations where Gemini CLI runs on untrusted inputs with `--yolo` (e.g. CI workflows that triage user-submitted GitHub issues where we recommend a strict allowlist). If used with untrusted content and a tool allowlist that permits `run_shell_command`, this could lead to remote code execution via prompt injection. In version `0.39.1`, the Gemini CLI policy engine now evaluates tool allowlisting under `--yolo` mode, which is useful for CI workflows that allowlist a few safe commands to run when processing untrusted inputs. As a result, some workflows that previously depended on this behavior may fail silently unless tool allowlists are modified to fit the task. # Impact This impact is limited to workflows using Gemini CLI in headless mode. Any use of Gemini CLI in headless mode without folder trust will require manual review to correctly configure folder trust. **This affects all Gemini CLI GitHub Actions.** Users must review their workflows, and take one of two approaches: 1\. If the workflow runs on trusted inputs (e.g. reviewing PRs from trusted collaborators), set `GEMINI_TRUST_WORKSPACE: 'true'` in your workflow. 2\. If the workflow runs on untrusted inputs, review our guidance in [google-github-actions/run-gemini-cli](https://github.com/google-github-actions/run-gemini-cli) to harden your workflow against m | H10: https://github.com/advisories/GHSA-wpqr-6v78-jr5g
A11: CA-117 | B11: W2 pilot | C11: Cline | D11: ecosystem | E11: 2026-05-08 | F11: Cline Kanban Server has a Cross-Origin WebSocket Hijacking Vulnerability | G11: ## Summary The `kanban` npm package (used by the `cline` CLI) starts a WebSocket server on `127.0.0.1:3484` with no Origin header validation. Any website a developer visits can silently connect to the kanban server via WebSocket and: 1. Leak sensitive data in real-time: workspace filesystem paths, task titles/descriptions, git branch info, AI agent chat messages 2. Hijack running AI agent terminals by injecting arbitrary prompts into the agent's input, leading to remote code execution 3. Kill running agent tasks by terminating active sessions via the control WebSocket WebSocket connections are not subject to CORS restrictions. The browser sends them freely to localhost regardless of the page's origin. The kanban server accepts all connections without checking the Origin header. ## Affected Component - Package: `kanban` on npm (https://www.npmjs.com/package/kanban) - Repository: https://github.com/cline/kanban - Tested version: 0.1.59 - Installed via: `cline` CLI (`cline --kanban` or default `cline` command) - Endpoints: `ws://127.0.0.1:3484/api/runtime/ws`, `ws://127.0.0.1:3484/api/terminal/io`, `ws://127.0.0.1:3484/api/terminal/control` ## Root Cause Three WebSocket endpoints are exposed without authentication or Origin validation. ### 1. Runtime state stream (no Origin check on upgrade) ```javascript server.on("upgrade", (request, socket, head) => { if (normalizeRequestPath(requestUrl.pathname) !== "/api/runtime/ws") { return; } // No Origin header validation. Any website can connect. deps.runtimeStateHub.handleUpgrade(request, socket, head, { requestedWorkspaceId }); }); ``` On connection, the server immediately sends a full snapshot of the developer's workspace: ```javascript sendRuntimeStateMessage(client, { type: "snapshot", currentProjectId: projectsPayload.currentProjectId, projects: projectsPayload.projects, // filesystem paths workspaceState, // tasks, git info, board workspaceMetadata, // git summary clineSessionContextVersion }); ``` ### 2. Terminal I/O (raw bytes written to agent terminal, no auth) ```javascript ioServer.on("connection", (ws, context2) => { ws.on("message", (rawMessage) => { // Attacker's bytes written directly to the agent PTY terminalManager.writeInput(taskId, rawDataToBuffer(rawMessage)); }); }); ``` ### 3. Terminal control (can kill tasks, no auth) ```javascript controlServer.on("connection", (ws, context2) => { ws.on("message", (rawMessage) => { const message = parseWebSocketPayload(rawMessage); if (message.type === "stop") { terminalManager.stopTaskSession(taskId); } }); }); ``` ## Exploitation ### Step 1: Cross-Origin Info Leak From any website, JavaScript connects to the runtime WebSocket. No CORS applies: ```javascript // Run this on https://example.com. It connects to the victim's local kanban. const ws = new WebSocket | H11: https://github.com/advisories/GHSA-5c57-rqjx-35g2
A12: CA-132 | B12: W2 pilot | C12: Other coding agent | D12: agent product | E12: 2026-05-28 | F12: CodeWhale: run_tests Tool Enables RCE via Malicious Repository Without Approval | G12: CodeWhale is a DeepSeek + MiMo coding agent in terminal. From 0.3.0 to 0.8.23, the run_tests tool executes cargo test in the workspace with ApprovalRequirement::Auto, meaning it runs without any user approval prompt. cargo test compiles and executes arbitrary code: test binaries, build.rs build scripts, and proc macros. While auto-approving test execution is a deliberate design choice, it creates an inconsistency in the security boundary. However, in a malicious repository, test code can execute arbitrary shell commands, exfiltrate credentials, or establish persistence with zero approval. The attack is amplified by AGENTS.md (auto-loaded into the system prompt), which can instruct the model to run tests proactively at session start. This vulnerability is fixed in 0.8.23. | H12: https://www.cve.org/CVERecord?id=CVE-2026-45311
... A14: CA-135 | B14: W2 pilot | C14: Claude Code | D14: ecosystem | E14: 2026-05-28 | F14: nono: Sandbox escape on Linux via D-Bus: `systemd-run --user` | G14: ### Summary The nono Landlock/seccomp policies allow access to local Unix domain sockets (concrete and abstract). This allows an easy sandbox escape by talking to the per-user systemd dbus socket. Threat scenario: Running Aider, Claude Code, OpenCode or similar tools with "allow bash" policy so that it can invoke arbitrary host tools like `make`, `gcc`, etc. to write code. ### Reproducer Here, instead of running a tool like `opencode` or `claude` one can just invoke `systemd-run`, but this is something an agent could be tricked into doing: ```bash $ cd ~/src/myproject $ nono run -s --allow-cwd --profile claude-code -- \ systemd-run --user -q --wait --collect \ /bin/sh -c "echo oops > ~/Documents/escaped.txt" $ cat /var/home/test/Documents/escaped.txt oops $ ``` ### Impact Complete sandbox escape. The unsandboxed sibling process can write anywhere the user can write, spawn arbitrary processes with network access, etc. ### Maintainer Context This issue allows a process running inside the sandbox to escape confinement by interacting with local user-scoped IPC mechanisms and regain the authority already held by the invoking user or service account. The issue impacts the sandbox’s confinement and blast-radius reduction guarantees for agents and sandboxed tooling. However, exploitation does not provide privilege escalation, cross-user access, or host compromise beyond the permissions already available to the launcher outside the sandbox. This issue affects the CLI policy layer and bundled sandbox profiles. The underlying core library `nono` does not ship with policy definitions or agent-facing confinement profiles by default, nor do the language SDKs. This is considered a serious issue because an AI agent or untrusted command stream operating within the sandbox could abuse the bypass to perform unauthorized or destructive actions using the delegated authority of the launching user. The root cause was incomplete mediation of local Unix domain socket access within affected sandbox policies. Support for restricting this behavior has since been added and the fix is available in the repository pending release. CVSS rationale: exploitation requires execution within a locally launched sandboxed process using the authority already delegated by the invoking user or service account (`AV:L/PR:L`). The issue allows reliable bypass of sandbox confinement and policy guarantees, resulting in high integrity impact (`I:H`) and limited availability impact (`A:L`) through destructive actions within the launcher’s existing permissions. However, the issue does not provide privilege escalation, cross-user access, or a change in security scope (`S:U`). | H14: https://github.com/advisories/GHSA-27vp-2mmc-vmh3
A15: CA-141 | B15: W2 pilot | C15: GitHub Copilot | D15: agent product | E15: 2026-06-09 | G15: Improper limitation of a pathname to a restricted directory ('path traversal') in GitHub Copilot and Visual Studio Code allows an unauthorized attacker to bypass a security feature locally. | H15: https://github.com/advisories/GHSA-f78m-9xhc-p52v
A16: CA-145 | B16: W2 pilot | C16: Claude Code | D16: agent product | E16: 2026-06-17 | F16: Claude Code: Out-of-Band Data Exfiltration via Pre-Approved HuggingFace Domain in WebFetch | G16: Because the hostname huggingface.co was pre-approved as a bare hostname for the WebFetch tool, any path on that domain—including attacker-controlled model repositories—was auto-approved without a permission prompt or being subject to --allowedTools restrictions. An attacker able to inject untrusted content into a Claude Code context could direct it to issue WebFetch requests against attacker-controlled repository files (e.g. /resolve/main/config.json), which HuggingFace counts as downloads server-side, creating a covert out-of-band channel for encoding and exfiltrating data Claude can access such as files, environment variables, or command output. Reliably exploiting this required the ability to add untrusted content into a Claude Code context window. Users on standard Claude Code auto-update have received this fix already; users performing manual updates are advised to update to the latest version. Thank you to hackerone.com/novee for reporting this issue. | H16: https://github.com/advisories/GHSA-fg94-h982-f3mm
A17: CA-153 | B17: W2 pilot | C17: Other coding agent | D17: ecosystem | E17: 2026-06-24 | F17: chrome-devtools-mcp: daemon.pid write follows symlinks in /tmp fallback runtime directory | G17: Chrome DevTools for agents (chrome-devtools-mcp) lets your coding agent control and inspect a live Chrome browser. From 0.20.0 until 1.1.0, The chrome-devtools-mcp daemon writes its PID file with fs.writeFileSync() to a deterministic runtime path. On typical macOS environments, and on Linux sessions where $XDG_RUNTIME_DIR is unset, that runtime path falls back to /tmp/chrome-devtools-mcp-<uid>/daemon.pid. Because the write does not use O_NOFOLLOW, a local low-privilege user on the same POSIX host can pre-create /tmp/chrome-devtools-mcp-<victim_uid>/daemon.pid as a symlink to a file writable by the victim. When the victim later starts daemon mode, fs.writeFileSync() follows the symlink and truncates the target file to the daemon PID string. This vulnerability is fixed in 1.1.0. | H17: https://www.cve.org/CVERecord?id=CVE-2026-53765
A18: CA-156 | B18: W2 pilot | C18: Cursor | D18: agent product | E18: 2026-06-25 | F18: Cursor Desktop sandbox escape via agent-controlled working directory | G18: Cursor is a code editor built for programming with AI. Prior to 3.0, Cursor runs agent terminal commands in a sandbox by default, and the sandbox grants write access to the command's working directory. A flaw was identified in how the agent could modify the working_directory parameter, which could cause the sandbox to include writable paths outside the intended workspace. A malicious agent could set working_directory to a sensitive location and write arbitrary files outside the workspace under the user's privileges. This enables non-sandboxed Remote Code Execution — for example by overwriting the cursorsandbox helper so later commands run unsandboxed — with no user interaction beyond a benign prompt. This vulnerability is fixed in 3.0. | H18: https://www.cve.org/CVERecord?id=CVE-2026-50548
A19: CA-162 | B19: W2 pilot | C19: GitHub Copilot | D19: agent product | E19: 2026-07-14 | G19: Insufficiently protected credentials in GitHub Copilot and Visual Studio Code allows an unauthorized attacker to disclose information over a network. | H19: https://github.com/advisories/GHSA-3v99-gw88-f2cw
A20: CA-172 | B20: W2 pilot | C20: Other coding agent | D20: ecosystem | E20: 2026-08-03 | F20: Ouroboros: Untrusted project .env can still reach RCE via omitted execution-routing keys (Incomplete fix of CVE-2026-47211) | G20: Ouroboros is a local-first runtime for AI coding agents that records their actions and applies user-defined policies to constrain behavior. Versions prior to 0.42.1 have an incomplete denylist. Several execution-routing keys of the same RCE class were omitted, so a malicious cloned repo can still reach arbitrary command execution by shipping a .env (auto-loaded at import, with no review step). The CVE-2026-47211 fix added _UNTRUSTED_ENV_DENYLIST to stop an untrusted project-directory .env from redirecting execution, but it did not account for all keys. The backend config-home and MCP/plugin roots bypass the approval gate by pointing the nested agent, MCP servers, and plugin roster at attacker config. Other variables re-enable blocked local transports, replace sub-agent prompts, switch backends, and lower tool approval classes, further weakening the approval gate. This issue has been fixed in version 0.42.1. | H20: https://www.cve.org/CVERecord?id=CVE-2026-66065
A21: CA-200 | B21: W2 pilot | C21: Aider | D21: agent product | E21: 2026-09-04 | G21: aider (aider-chat) automatically loads a .aider.conf.yml configuration file from the root of the git repository it is launched in. A crafted repository can set test-cmd (executed at startup) or lint-cmd (executed on the first file edit), which aider runs through a shell (subprocess with shell=True) without any user confirmation, LLM interaction, or API key. Consequently, a user who clones and runs aider inside an attacker-supplied repository achieves arbitrary command execution on their machine. The behavior is long-standing and was confirmed on 0.86.3.dev (current main). | H21: https://github.com/advisories/GHSA-h3gc-qfjg-2m69
A22: CA-001 | B22: W3 | C22: Sourcegraph Cody/Amp | D22: agent product | E22: 2023-10-31 | F22: Overwrite of builtin Cody commands facilitates RCE | G22: Cody is an artificial intelligence (AI) coding assistant. The Cody AI VSCode extension versions 0.10.0 through 0.14.0 are vulnerable to Remote Code Execution under certain conditions. An attacker in control of a malicious repository could modify the Cody configuration file `.vscode/cody.json` and overwrite Cody commands. If a user with the extension installed opens this malicious repository and runs a Cody command such as /explain or /doc, this could allow arbitrary code execution on the user's machine. The vulnerability is rated as critical severity, but with low exploitability. It requires the user to have a malicious repository loaded and execute the overwritten command in VS Code. The issue is exploitable regardless of the user blocking code execution on a repository through VS Code Workspace Trust. The issue was found during a regular 3rd party penetration test. The maintainers of Cody do not have evidence of open source repositories having malicious `.vscode/cody.json` files to exploit this vulnerability. The issue is fixed in version 0.14.1 of the Cody VSCode extension. In case users can't promptly upgrade, they should not open any untrusted repositories with the Cody extension loaded. | H22: https://www.cve.org/CVERecord?id=CVE-2023-46248
A23: CA-002 | B23: W3 | C23: Cursor | D23: agent product | E23: 2024-10-22 | F23: RCE via Prompt Injection Into Cursor's Terminal Cmd-K | G23: Cursor is a code editor built for programming with AI. Prior to Sep 27, 2024, if a user generated a terminal command via Cursor's Terminal Cmd-K/Ctrl-K feature and if the user explicitly imported a malicious web page into the Terminal Cmd-K prompt, an attacker with control over the referenced web page could have a significant chance of influencing a language model to output arbitrary commands for execution in the user's terminal. This scenario would require the user explicitly opt-in to including the contents of a compromised webpage, and it would require that the attacker display prompt injection text in the the contents of the compromised webpage. A server-side patch to not stream back newlines or control characters was released on September 27, 2024, within two hours of the issue being reported. Additionally, Cursor 0.42 includes client-side mitigations to prevent any newline or control character from being streamed into the terminal directly. It also contains a new setting, `"cursor.terminal.usePreviewBox"`, which, if set to true, streams the response into a preview box whose contents then have to be manually accepted before being inserted into the terminal. This setting is useful if you're working in a shell environment where commands can be executed without pressing enter or any control character. The patch has been applied server-side, so no additional action is needed, even on older versions of Cursor. Separately, Cursor's maintainers also recommend, as best practice, to only include trusted pieces of context in prompts. | H23: https://www.cve.org/CVERecord?id=CVE-2024-48919
A24: CA-003 | B24: W3 | C24: Cursor | D24: ecosystem | E24: 2025-03-01 | G24: ToDesktop before 2024-10-03, as used by Cursor before 2024-10-03 and other applications, allows remote attackers to execute arbitrary commands on the build server (e.g., read secrets from the desktopify config.prod.json file), and consequently deploy updates to any app, via a postinstall script in package.json. No exploitation occurred. | H24: https://github.com/advisories/GHSA-6662-3hpj-63qq
A25: CA-004 | B25: W3 | C25: Cursor | D25: agent product | E25: 2025-04-08 | F25: Arbitrary file write from Cursor Agent through a prompt injection from malicious @Docs | G25: Cursor is a code editor built for programming with AI. In versions 0.45.0 through 0.48.6, the Cursor app introduced a regression affecting the set of file paths the Cursor Agent is permitted to modify automatically. Under specific conditions, the agent could be prompted, either directly by the user or via maliciously crafted context, to automatically write to files outside of the opened workspace. This behavior required deliberate prompting, making successful exploitation highly impractical in real-world scenarios. Furthermore, the edited file was still displayed in the UI as usual for user review, making it unlikely for the edit to go unnoticed by the user. This vulnerability is fixed in 0.48.7. | H25: https://www.cve.org/CVERecord?id=CVE-2025-32018
A26: CA-005 | B26: W3 | C26: Cursor | D26: agent product | E26: 2025-06-11 | F26: Cursor Agent Potentially Leaks Information using JSON schema | G26: Cursor is a code editor built for programming with AI. Prior to 0.51.0, by default, the setting json.schemaDownload.enable was set to True. This means that by writing a JSON file, an attacker can trigger an arbitrary HTTP GET request that does not require user confirmation. Since the Cursor Agent can edit JSON files, this means a malicious agent, for example, after a prompt injection attack already succeeded, could trigger a GET request to an attacker controlled URL, potentially exfiltrating other data the agent may have access to. This vulnerability is fixed in 0.51.0. | H26: https://www.cve.org/CVERecord?id=CVE-2025-49150
A27: CA-006 | B27: W3 | C27: Claude Code | D27: agent product | E27: 2025-06-23 | F27: Claude Code Improper Authorization via websocket connections from arbitrary origins | G27: Claude Code extensions in VSCode and forks (e.g., Cursor, Windsurf, and VSCodium) and JetBrains IDEs (e.g., IntelliJ, Pycharm, and Android Studio) are vulnerable to unauthorized websocket connections from an attacker when visiting attacker-controlled webpages. Claude Code for VSCode IDE extensions versions 0.2.116 through 1.0.23 are vulnerable. For Jetbrains IDE plugins, Claude Code [beta] versions 0.1.1 through 0.1.8 are vulnerable. In VSCode (and forks), exploitation would allow an attacker to read arbitrary files, see the list of files open in the IDE, get selection and diagnostics events from the IDE, or execute code in limited situations where a user has an open Jupyter Notebook and accepts a malicious prompt. In JetBrains IDEs, an attacker could get selection events, a list of open files, and a list of syntax errors. **Remediation** We released a patch for this issue on June 13th, 2025. Although Claude Code auto-updates when you launch it and auto-updates the extensions, you should take the following steps (the exact steps depend on your IDE). **VSCode, Cursor, Windsurf, VSCodium, and other VSCode forks** Extension Name: Claude Code for VSCode Instructions: 1. Open the list of Extensions (View->Extensions) 2. Look for Claude Code for VSCode among installed extensions 3. If you have a version < 1.0.24, click “Update” (or “Uninstall”) 4. Restart the IDE **All JetBrains IDEs including IntelliJ, PyCharm, and Android Studio** Plugin name: Claude Code [Beta] Instructions: 1. Open the Plugins list 2. Look for Claude Code [Beta] among installed extensions 3. Update (or Uninstall) the plugin if the version is < 0.1.9 4. Restart the IDE | H27: https://github.com/advisories/GHSA-9f65-56v6-gxw7
A28: CA-007 | B28: W3 | C28: Roo Code | D28: agent product | E28: 2025-06-27 | F28: Roo Code extension vulnerable to Potential Information Leakage via JSON Schema | G28: Roo Code is an AI-powered autonomous coding agent. Prior to version 3.20.3, there was an issue where the Roo Code agent's `search_files` tool did not respect the setting to disable reads outside of the VS Code workspace. This means that an attacker who was able to inject a prompt into the agent could potentially read a sensitive file and then write the information to a JSON schema. Users have the option to disable schema fetching in VS Code, but the feature is enabled by default. For users with this feature enabled, writing to the schema would trigger a network request without the user having a chance to deny. This issue is of moderate severity, since it requires the attacker to already be able to submit prompts to the agent. Version 3.20.3 fixed the issue where `search_files` did not respect the setting to limit it to the workspace. This reduces the scope of the damage if an attacker is able to take control of the agent through prompt injection or another vector. | H28: https://www.cve.org/CVERecord?id=CVE-2025-53097
A29: CA-008 | B29: W3 | C29: Roo Code | D29: agent product | E29: 2025-06-27 | F29: Roo Code Vulnerable to Potential Remote Code Execution via Model Context Protocol | G29: Roo Code is an AI-powered autonomous coding agent. The project-specific MCP configuration for the Roo Code agent is stored in the `.roo/mcp.json` file within the VS Code workspace. Because the MCP configuration format allows for execution of arbitrary commands, prior to version 3.20.3, it would have been possible for an attacker with access to craft a prompt to ask the agent to write a malicious command to the MCP configuration file. If the user had opted-in to auto-approving file writes within the project, this would have led to arbitrary command execution. This issue is of moderate severity, since it requires the attacker to already be able to submit prompts to the agent (for instance through a prompt injection attack), for the user to have MCP enabled (on by default), and for the user to have enabled auto-approved file writes (off by default). Version 3.20.3 fixes the issue by adding an additional layer of opt-in configuration for auto-approving writing to Roo's configuration files, including all files within the `.roo/` folder. | H29: https://www.cve.org/CVERecord?id=CVE-2025-53098
A30: CA-009 | B30: W3 | C30: Roo Code | D30: agent product | E30: 2025-07-07 | F30: Roo Code allows Potential Remote Code Execution via .vscode/settings.json | G30: Roo Code is an AI-powered autonomous coding agent. Prior to 3.22.6, if the victim had "Write" auto-approved, an attacker with the ability to submit prompts to the agent could write to VS Code settings files and trigger code execution. There were multiple ways to achieve that. One example is with the php.validate.executablePath setting which lets you set the path for the php executable for syntax validation. The attacker could have written the path to an arbitrary command there and then created a php file to trigger it. This vulnerability is fixed in 3.22.6. | H30: https://www.cve.org/CVERecord?id=CVE-2025-53536
A31: CA-010 | B31: W3 | C31: Roo Code | D31: agent product | E31: 2025-07-23 | F31: Roo Code Lacks Line Break Validation in its Command Execution Tool | G31: Roo Code is an AI-powered autonomous coding agent that lives in users' editors. In versions 3.23.18 and below, RooCode does not validate line breaks (\n) in its command input, allowing potential bypass of the allow-list mechanism. The project appears to lack parsing or validation logic to prevent multi-line command injection. When commands are evaluated for execution, only the first line or token may be considered, enabling attackers to smuggle additional commands in subsequent lines. This is fixed in version 3.23.19. | H31: https://www.cve.org/CVERecord?id=CVE-2025-54377
A32: CA-011 | B32: W3 | C32: OpenAI Codex | D32: agent product | E32: 2025-07-25 | G32: OpenAI Codex CLI before 0.9.0 auto-approves ripgrep (aka rg) execution even with the --pre or --hostname-bin or --search-zip or -z flag. | H32: https://github.com/advisories/GHSA-q6hp-29g8-7j6j
A33: CA-012 | B33: W3 | C33: Amazon Q Developer | D33: agent product | E33: 2025-07-30 | F33: Inert Malicious script injected into Amazon Q Developer Visual Studio Code (VS Code) Extension | G33: The Amazon Q Developer Visual Studio Code (VS Code) extension v1.84.0 contains inert, injected code designed to call the Q Developer CLI. The code executes when the extension is launched within the VS Code environment; however the injected code contains a syntax error which prevents it from making a successful API call to the Q Developer CLI. To mitigate this issue, users should upgrade to version v1.85.0. All installations of v1.84.0 should be removed from use. | H33: https://www.cve.org/CVERecord?id=CVE-2025-8217
A34: CA-014 | B34: W3 | C34: Cursor | D34: agent product | E34: 2025-08-01 | F34: Cursor's Mermaid Diagram Tool is Vulnerable to an Arbitrary Image Fetch | G34: Cursor is a code editor built for programming with AI. In versions below 1.3, Mermaid (which is used to render diagrams) allows embedding images which then get rendered by Cursor in the chat box. An attacker can use this to exfiltrate sensitive information to a third-party attacker controlled server through an image fetch after successfully performing a prompt injection. A malicious model (or hallucination/backdoor) might also trigger this exploit at will. This issue requires prompt injection from malicious data (web, image upload, source code) in order to exploit. In that case, it can send sensitive information to an attacker-controlled external server. This is fixed in version 1.3. | H34: https://www.cve.org/CVERecord?id=CVE-2025-54132
A35: CA-015 | B35: W3 | C35: Cursor | D35: agent product | E35: 2025-08-01 | F35: Cursor's MCP Install Deeplink Does Not Show Arguments in its User-Dialog | G35: Cursor is a code editor built for programming with AI. In versions 1.17 through 1.2, there is a UI information disclosure vulnerability in Cursor's MCP (Model Context Protocol) deeplink handler, allowing attackers to execute 2-click arbitrary system commands through social engineering attacks. When users click malicious `cursor://anysphere.cursor-deeplink/mcp/install` links, the installation dialog does not show the arguments being passed to the command being run. If a user clicks a malicious deeplink, then examines the installation dialog and clicks through, the full command including the arguments will be executed on the machine. This is fixed in version 1.3. | H35: https://www.cve.org/CVERecord?id=CVE-2025-54133
A36: CA-016 | B36: W3 | C36: Cursor | D36: agent product | E36: 2025-08-01 | F36: Cursor's Modification of MCP Server Definitions Bypasses Manual Re-approvals | G36: Cursor is a code editor built for programming with AI. In versions 1.2.4 and below, attackers can achieve remote and persistent code execution by modifying an already trusted MCP configuration file inside a shared GitHub repository or editing the file locally on the target's machine. Once a collaborator accepts a harmless MCP, the attacker can silently swap it for a malicious command (e.g., calc.exe) without triggering any warning or re-prompt. If an attacker has write permissions on a user's active branches of a source repository that contains existing MCP servers the user has previously approved, or allows an attacker has arbitrary file-write locally, the attacker can achieve arbitrary code execution. This is fixed in version 1.3. | H36: https://www.cve.org/CVERecord?id=CVE-2025-54136
A37: CA-017 | B37: W3 | C37: Claude Code | D37: agent product | E37: 2025-08-04 | F37: Claude Code Research Preview has a Path Restriction Bypass which could allow unauthorized file access | G37: Due to a path validation flaw using prefix matching instead of canonical path comparison, it was possible to bypass directory restrictions and access files outside the CWD. Successful exploitation depends on the presence of (or ability to create) a directory with the same prefix as the CWD and the ability to add untrusted content into a Claude Code context window. Users on standard Claude Code auto-update received this fix automatically after release. Current users of Claude Code are unaffected, as versions prior to 1.0.24 are deprecated and have been forced to update. Thank you to Elad Beber (Cymulate) for reporting this issue! | H37: https://github.com/advisories/GHSA-pmw4-pwvc-3hx2
A38: CA-018 | B38: W3 | C38: Claude Code | D38: agent product | E38: 2025-08-04 | F38: Claude Code echo command allowed bypass of user approval prompt for command execution | G38: Due to an error in command parsing, it was possible to bypass the Claude Code confirmation prompt to trigger execution of an untrusted command. Reliably exploiting this requires the ability to add untrusted content into a Claude Code context window. Users on standard Claude Code auto-update received this fix automatically after release. Current users of Claude Code are unaffected, as versions prior to 1.0.24 are deprecated and have been forced to update. Thank you to Elad Beber (Cymulate) for reporting this issue! | H38: https://github.com/advisories/GHSA-x56v-x2h6-7j34
A39: CA-019 | B39: W3 | C39: Cursor | D39: agent product | E39: 2025-08-05 | F39: Cursor Agent is vulnerable prompt injection via Editor Special Files | G39: Cursor is a code editor built for programming with AI. Cursor allows writing in-workspace files with no user approval in versions less than 1.3.9. If the file is a dotfile, editing it requires approval but creating a new one doesn't. Hence, if sensitive editor files, such as the .vscode/settings.json file don't already exist in the workspace, an attacker can chain a indirect prompt injection vulnerability to hijack the context to write to the settings file and trigger RCE on the victim without user approval. This is fixed in version 1.3.9. | H39: https://www.cve.org/CVERecord?id=CVE-2025-54130
A40: CA-021 | B40: W3 | C40: Zed | D40: agent product | E40: 2025-08-11 | F40: Zed AI Agent Remote Code Execution | G40: Zed is a multiplayer code editor. Prior to version 0.197.3, in the Zed Agent Panel allowed for an AI agent to achieve Remote Code Execution (RCE) by bypassing user permission checks. An AI Agent could have exploited a permissions bypass vulnerability to create or modify a project-specific configuration file, leading to the execution of arbitrary commands on a victim's machine without the explicit approval that would otherwise be required. This vulnerability has been patched in version 0.197.3. A workaround for this issue involves either avoid sending prompts to the Agent Panel, or to limit the AI Agent's file system access. | H40: https://www.cve.org/CVERecord?id=CVE-2025-55012
A41: CA-022 | B41: W3 | C41: GitHub Copilot | D41: agent product | E41: 2025-08-12 | G41: Improper neutralization of special elements used in a command ('command injection') in GitHub Copilot and Visual Studio allows an unauthorized attacker to execute code locally. | H41: https://github.com/advisories/GHSA-3m2x-p87c-pwv6
...

Sheet Coder1
A1: case_id | B1: batch | C1: product | D1: title | E1: d1 | F1: d2 | G1: d3 | H1: d4 | I1: d5 | J1: d6 | K1: d7 | L1: d8 | M1: primary_domain | N1: c01 | O1: c02 | P1: c03 | Q1: c04 | R1: c05 | S1: c06 | T1: c07 | U1: c08 | V1: c09 | W1: c10 | X1: c11 | Y1: c12 | Z1: c13 | AA1: c14 | AB1: c15 | AC1: c16 | AD1: c17 | AE1: c18 | AF1: c19 | AG1: c20 | AH1: covered | AI1: n_domains | AJ1: n_applicable | AK1: n_breached | AL1: gcs | AM1: check | AN1: done | AO1: notes
A2: =Cases!A2 | B2: =Cases!B2 | C2: =Cases!C2 | D2: =IF(Cases!F2="",LEFT(Cases!G2,120),Cases!F2) | AI2: =IF(COUNT(E2:L2)=0,"",SUM(E2:L2)) | AJ2: =IF(AI2="","",N(E2)*3+N(F2)*2+N(G2)*2+N(H2)*2+N(I2)*2+N(J2)*3+N(K2)*3+N(L2)*3) | AK2: =IF(AI2="","",COUNTIF(N2:AG2,1)) | AL2: =IF(OR(AJ2="",AJ2=0),"",ROUND(100*(AJ2-AK2)/AJ2,1)) | AM2: =IF(AI2="","",IF(AI2=0,"No domain coded 1; ","")&IF(M2="","Primary domain missing; ",IF(IFERROR(INDEX(E2:L2,1,M2),0)<>1,"Primary domain not coded 1; ",""))&IF(COUNT(N2:AG2)<>AJ2,"Code 1 or 0 for exactly the controls of domains coded 1 (NA for the rest); ","")&IF(AH2="","Covered missing; ","")) | AN2: =IF(AND(AI2<>"",AM2=""),1,0)
A3: =Cases!A3 | B3: =Cases!B3 | C3: =Cases!C3 | D3: =IF(Cases!F3="",LEFT(Cases!G3,120),Cases!F3) | AI3: =IF(COUNT(E3:L3)=0,"",SUM(E3:L3)) | AJ3: =IF(AI3="","",N(E3)*3+N(F3)*2+N(G3)*2+N(H3)*2+N(I3)*2+N(J3)*3+N(K3)*3+N(L3)*3) | AK3: =IF(AI3="","",COUNTIF(N3:AG3,1)) | AL3: =IF(OR(AJ3="",AJ3=0),"",ROUND(100*(AJ3-AK3)/AJ3,1)) | AM3: =IF(AI3="","",IF(AI3=0,"No domain coded 1; ","")&IF(M3="","Primary domain missing; ",IF(IFERROR(INDEX(E3:L3,1,M3),0)<>1,"Primary domain not coded 1; ",""))&IF(COUNT(N3:AG3)<>AJ3,"Code 1 or 0 for exactly the controls of domains coded 1 (NA for the rest); ","")&IF(AH3="","Covered missing; ","")) | AN3: =IF(AND(AI3<>"",AM3=""),1,0)
A4: =Cases!A4 | B4: =Cases!B4 | C4: =Cases!C4 | D4: =IF(Cases!F4="",LEFT(Cases!G4,120),Cases!F4) | AI4: =IF(COUNT(E4:L4)=0,"",SUM(E4:L4)) | AJ4: =IF(AI4="","",N(E4)*3+N(F4)*2+N(G4)*2+N(H4)*2+N(I4)*2+N(J4)*3+N(K4)*3+N(L4)*3) | AK4: =IF(AI4="","",COUNTIF(N4:AG4,1)) | AL4: =IF(OR(AJ4="",AJ4=0),"",ROUND(100*(AJ4-AK4)/AJ4,1)) | AM4: =IF(AI4="","",IF(AI4=0,"No domain coded 1; ","")&IF(M4="","Primary domain missing; ",IF(IFERROR(INDEX(E4:L4,1,M4),0)<>1,"Primary domain not coded 1; ",""))&IF(COUNT(N4:AG4)<>AJ4,"Code 1 or 0 for exactly the controls of domains coded 1 (NA for the rest); ","")&IF(AH4="","Covered missing; ","")) | AN4: =IF(AND(AI4<>"",AM4=""),1,0)
A5: =Cases!A5 | B5: =Cases!B5 | C5: =Cases!C5 | D5: =IF(Cases!F5="",LEFT(Cases!G5,120),Cases!F5) | AI5: =IF(COUNT(E5:L5)=0,"",SUM(E5:L5)) | AJ5: =IF(AI5="","",N(E5)*3+N(F5)*2+N(G5)*2+N(H5)*2+N(I5)*2+N(J5)*3+N(K5)*3+N(L5)*3) | AK5: =IF(AI5="","",COUNTIF(N5:AG5,1)) | AL5: =IF(OR(AJ5="",AJ5=0),"",ROUND(100*(AJ5-AK5)/AJ5,1)) | AM5: =IF(AI5="","",IF(AI5=0,"No domain coded 1; ","")&IF(M5="","Primary domain missing; ",IF(IFERROR(INDEX(E5:L5,1,M5),0)<>1,"Primary domain not coded 1; ",""))&IF(COUNT(N5:AG5)<>AJ5,"Code 1 or 0 for exactly the controls of domains coded 1 (NA for the rest); ","")&IF(AH5="","Covered missing; ","")) | AN5: =IF(AND(AI5<>"",AM5=""),1,0)
A6: =Cases!A6 | B6: =Cases!B6 | C6: =Cases!C6 | D6: =IF(Cases!F6="",LEFT(Cases!G6,120),Cases!F6) | AI6: =IF(COUNT(E6:L6)=0,"",SUM(E6:L6)) | AJ6: =IF(AI6="","",N(E6)*3+N(F6)*2+N(G6)*2+N(H6)*2+N(I6)*2+N(J6)*3+N(K6)*3+N(L6)*3) | AK6: =IF(AI6="","",COUNTIF(N6:AG6,1)) | AL6: =IF(OR(AJ6="",AJ6=0),"",ROUND(100*(AJ6-AK6)/AJ6,1)) | AM6: =IF(AI6="","",IF(AI6=0,"No domain coded 1; ","")&IF(M6="","Primary domain missing; ",IF(IFERROR(INDEX(E6:L6,1,M6),0)<>1,"Primary domain not coded 1; ",""))&IF(COUNT(N6:AG6)<>AJ6,"Code 1 or 0 for exactly the controls of domains coded 1 (NA for the rest); ","")&IF(AH6="","Covered missing; ","")) | AN6: =IF(AND(AI6<>"",AM6=""),1,0)
A7: =Cases!A7 | B7: =Cases!B7 | C7: =Cases!C7 | D7: =IF(Cases!F7="",LEFT(Cases!G7,120),Cases!F7) | AI7: =IF(COUNT(E7:L7)=0,"",SUM(E7:L7)) | AJ7: =IF(AI7="","",N(E7)*3+N(F7)*2+N(G7)*2+N(H7)*2+N(I7)*2+N(J7)*3+N(K7)*3+N(L7)*3) | AK7: =IF(AI7="","",COUNTIF(N7:AG7,1)) | AL7: =IF(OR(AJ7="",AJ7=0),"",ROUND(100*(AJ7-AK7)/AJ7,1)) | AM7: =IF(AI7="","",IF(AI7=0,"No domain coded 1; ","")&IF(M7="","Primary domain missing; ",IF(IFERROR(INDEX(E7:L7,1,M7),0)<>1,"Primary domain not coded 1; ",""))&IF(COUNT(N7:AG7)<>AJ7,"Code 1 or 0 for exactly the controls of domains coded 1 (NA for the rest); ","")&IF(AH7="","Covered missing; ","")) | AN7: =IF(AND(AI7<>"",AM7=""),1,0)
A8: =Cases!A8 | B8: =Cases!B8 | C8: =Cases!C8 | D8: =IF(Cases!F8="",LEFT(Cases!G8,120),Cases!F8) | AI8: =IF(COUNT(E8:L8)=0,"",SUM(E8:L8)) | AJ8: =IF(AI8="","",N(E8)*3+N(F8)*2+N(G8)*2+N(H8)*2+N(I8)*2+N(J8)*3+N(K8)*3+N(L8)*3) | AK8: =IF(AI8="","",COUNTIF(N8:AG8,1)) | AL8: =IF(OR(AJ8="",AJ8=0),"",ROUND(100*(AJ8-AK8)/AJ8,1)) | AM8: =IF(AI8="","",IF(AI8=0,"No domain coded 1; ","")&IF(M8="","Primary domain missing; ",IF(IFERROR(INDEX(E8:L8,1,M8),0)<>1,"Primary domain not coded 1; ",""))&IF(COUNT(N8:AG8)<>AJ8,"Code 1 or 0 for exactly the controls of domains coded 1 (NA for the rest); ","")&IF(AH8="","Covered missing; ","")) | AN8: =IF(AND(AI8<>"",AM8=""),1,0)
A9: =Cases!A9 | B9: =Cases!B9 | C9: =Cases!C9 | D9: =IF(Cases!F9="",LEFT(Cases!G9,120),Cases!F9) | AI9: =IF(COUNT(E9:L9)=0,"",SUM(E9:L9)) | AJ9: =IF(AI9="","",N(E9)*3+N(F9)*2+N(G9)*2+N(H9)*2+N(I9)*2+N(J9)*3+N(K9)*3+N(L9)*3) | AK9: =IF(AI9="","",COUNTIF(N9:AG9,1)) | AL9: =IF(OR(AJ9="",AJ9=0),"",ROUND(100*(AJ9-AK9)/AJ9,1)) | AM9: =IF(AI9="","",IF(AI9=0,"No domain coded 1; ","")&IF(M9="","Primary domain missing; ",IF(IFERROR(INDEX(E9:L9,1,M9),0)<>1,"Primary domain not coded 1; ",""))&IF(COUNT(N9:AG9)<>AJ9,"Code 1 or 0 for exactly the controls of domains coded 1 (NA for the rest); ","")&IF(AH9="","Covered missing; ","")) | AN9: =IF(AND(AI9<>"",AM9=""),1,0)
A10: =Cases!A10 | B10: =Cases!B10 | C10: =Cases!C10 | D10: =IF(Cases!F10="",LEFT(Cases!G10,120),Cases!F10) | AI10: =IF(COUNT(E10:L10)=0,"",SUM(E10:L10)) | AJ10: =IF(AI10="","",N(E10)*3+N(F10)*2+N(G10)*2+N(H10)*2+N(I10)*2+N(J10)*3+N(K10)*3+N(L10)*3) | AK10: =IF(AI10="","",COUNTIF(N10:AG10,1)) | AL10: =IF(OR(AJ10="",AJ10=0),"",ROUND(100*(AJ10-AK10)/AJ10,1)) | AM10: =IF(AI10="","",IF(AI10=0,"No domain coded 1; ","")&IF(M10="","Primary domain missing; ",IF(IFERROR(INDEX(E10:L10,1,M10),0)<>1,"Primary domain not coded 1; ",""))&IF(COUNT(N10:AG10)<>AJ10,"Code 1 or 0 for exactly the controls of domains coded 1 (NA for the rest); ","")&IF(AH10="","Covered missing; ","")) | AN10: =IF(AND(AI10<>"",AM10=""),1,0)
A11: =Cases!A11 | B11: =Cases!B11 | C11: =Cases!C11 | D11: =IF(Cases!F11="",LEFT(Cases!G11,120),Cases!F11) | AI11: =IF(COUNT(E11:L11)=0,"",SUM(E11:L11)) | AJ11: =IF(AI11="","",N(E11)*3+N(F11)*2+N(G11)*2+N(H11)*2+N(I11)*2+N(J11)*3+N(K11)*3+N(L11)*3) | AK11: =IF(AI11="","",COUNTIF(N11:AG11,1)) | AL11: =IF(OR(AJ11="",AJ11=0),"",ROUND(100*(AJ11-AK11)/AJ11,1)) | AM11: =IF(AI11="","",IF(AI11=0,"No domain coded 1; ","")&IF(M11="","Primary domain missing; ",IF(IFERROR(INDEX(E11:L11,1,M11),0)<>1,"Primary domain not coded 1; ",""))&IF(COUNT(N11:AG11)<>AJ11,"Code 1 or 0 for exactly the controls of domains coded 1 (NA for the rest); ","")&IF(AH11="","Covered missing; ","")) | AN11: =IF(AND(AI11<>"",AM11=""),1,0)
A12: =Cases!A12 | B12: =Cases!B12 | C12: =Cases!C12 | D12: =IF(Cases!F12="",LEFT(Cases!G12,120),Cases!F12) | AI12: =IF(COUNT(E12:L12)=0,"",SUM(E12:L12)) | AJ12: =IF(AI12="","",N(E12)*3+N(F12)*2+N(G12)*2+N(H12)*2+N(I12)*2+N(J12)*3+N(K12)*3+N(L12)*3) | AK12: =IF(AI12="","",COUNTIF(N12:AG12,1)) | AL12: =IF(OR(AJ12="",AJ12=0),"",ROUND(100*(AJ12-AK12)/AJ12,1)) | AM12: =IF(AI12="","",IF(AI12=0,"No domain coded 1; ","")&IF(M12="","Primary domain missing; ",IF(IFERROR(INDEX(E12:L12,1,M12),0)<>1,"Primary domain not coded 1; ",""))&IF(COUNT(N12:AG12)<>AJ12,"Code 1 or 0 for exactly the controls of domains coded 1 (NA for the rest); ","")&IF(AH12="","Covered missing; ","")) | AN12: =IF(AND(AI12<>"",AM12=""),1,0)
A13: =Cases!A13 | B13: =Cases!B13 | C13: =Cases!C13 | D13: =IF(Cases!F13="",LEFT(Cases!G13,120),Cases!F13) | AI13: =IF(COUNT(E13:L13)=0,"",SUM(E13:L13)) | AJ13: =IF(AI13="","",N(E13)*3+N(F13)*2+N(G13)*2+N(H13)*2+N(I13)*2+N(J13)*3+N(K13)*3+N(L13)*3) | AK13: =IF(AI13="","",COUNTIF(N13:AG13,1)) | AL13: =IF(OR(AJ13="",AJ13=0),"",ROUND(100*(AJ13-AK13)/AJ13,1)) | AM13: =IF(AI13="","",IF(AI13=0,"No domain coded 1; ","")&IF(M13="","Primary domain missing; ",IF(IFERROR(INDEX(E13:L13,1,M13),0)<>1,"Primary domain not coded 1; ",""))&IF(COUNT(N13:AG13)<>AJ13,"Code 1 or 0 for exactly the controls of domains coded 1 (NA for the rest); ","")&IF(AH13="","Covered missing; ","")) | AN13: =IF(AND(AI13<>"",AM13=""),1,0)
... A224: =Cases!A224 | B224: =Cases!B224 | C224: =Cases!C224 | D224: =IF(Cases!F224="",LEFT(Cases!G224,120),Cases!F224) | AI224: =IF(COUNT(E224:L224)=0,"",SUM(E224:L224)) | AJ224: =IF(AI224="","",N(E224)*3+N(F224)*2+N(G224)*2+N(H224)*2+N(I224)*2+N(J224)*3+N(K224)*3+N(L224)*3) | AK224: =IF(AI224="","",COUNTIF(N224:AG224,1)) | AL224: =IF(OR(AJ224="",AJ224=0),"",ROUND(100*(AJ224-AK224)/AJ224,1)) | AM224: =IF(AI224="","",IF(AI224=0,"No domain coded 1; ","")&IF(M224="","Primary domain missing; ",IF(IFERROR(INDEX(E224:L224,1,M224),0)<>1,"Primary domain not coded 1; ",""))&IF(COUNT(N224:AG224)<>AJ224,"Code 1 or 0 for exactly the controls of domains coded 1 (NA for the rest); ","")&IF(AH224="","Covered missing; ","")) | AN224: =IF(AND(AI224<>"",AM224=""),1,0)

Sheet Coder2
A1: case_id | B1: batch | C1: product | D1: title | E1: d1 | F1: d2 | G1: d3 | H1: d4 | I1: d5 | J1: d6 | K1: d7 | L1: d8 | M1: primary_domain | N1: c01 | O1: c02 | P1: c03 | Q1: c04 | R1: c05 | S1: c06 | T1: c07 | U1: c08 | V1: c09 | W1: c10 | X1: c11 | Y1: c12 | Z1: c13 | AA1: c14 | AB1: c15 | AC1: c16 | AD1: c17 | AE1: c18 | AF1: c19 | AG1: c20 | AH1: covered | AI1: n_domains | AJ1: n_applicable | AK1: n_breached | AL1: gcs | AM1: check | AN1: done | AO1: notes
A2: =Cases!A2 | B2: =Cases!B2 | C2: =Cases!C2 | D2: =IF(Cases!F2="",LEFT(Cases!G2,120),Cases!F2) | AI2: =IF(COUNT(E2:L2)=0,"",SUM(E2:L2)) | AJ2: =IF(AI2="","",N(E2)*3+N(F2)*2+N(G2)*2+N(H2)*2+N(I2)*2+N(J2)*3+N(K2)*3+N(L2)*3) | AK2: =IF(AI2="","",COUNTIF(N2:AG2,1)) | AL2: =IF(OR(AJ2="",AJ2=0),"",ROUND(100*(AJ2-AK2)/AJ2,1)) | AM2: =IF(AI2="","",IF(AI2=0,"No domain coded 1; ","")&IF(M2="","Primary domain missing; ",IF(IFERROR(INDEX(E2:L2,1,M2),0)<>1,"Primary domain not coded 1; ",""))&IF(COUNT(N2:AG2)<>AJ2,"Code 1 or 0 for exactly the controls of domains coded 1 (NA for the rest); ","")&IF(AH2="","Covered missing; ","")) | AN2: =IF(AND(AI2<>"",AM2=""),1,0)
A3: =Cases!A3 | B3: =Cases!B3 | C3: =Cases!C3 | D3: =IF(Cases!F3="",LEFT(Cases!G3,120),Cases!F3) | AI3: =IF(COUNT(E3:L3)=0,"",SUM(E3:L3)) | AJ3: =IF(AI3="","",N(E3)*3+N(F3)*2+N(G3)*2+N(H3)*2+N(I3)*2+N(J3)*3+N(K3)*3+N(L3)*3) | AK3: =IF(AI3="","",COUNTIF(N3:AG3,1)) | AL3: =IF(OR(AJ3="",AJ3=0),"",ROUND(100*(AJ3-AK3)/AJ3,1)) | AM3: =IF(AI3="","",IF(AI3=0,"No domain coded 1; ","")&IF(M3="","Primary domain missing; ",IF(IFERROR(INDEX(E3:L3,1,M3),0)<>1,"Primary domain not coded 1; ",""))&IF(COUNT(N3:AG3)<>AJ3,"Code 1 or 0 for exactly the controls of domains coded 1 (NA for the rest); ","")&IF(AH3="","Covered missing; ","")) | AN3: =IF(AND(AI3<>"",AM3=""),1,0)
